Workbook

Sheet Summary
A1: 3affya screen inventory
A2: Draft 2, 19 Oct 2026. Draft 1 listed the screens from project notes section 6 and the tasks file. Draft 2 adds column L (Design pointers) and M (Rule refs) from the 19 Oct research, and N (Layout call: the stack top to bottom, above the fold, the hook; one judgement per screen); rule IDs are on the Rules sheet and in programmx_aafia-screen-rules_2026-10.pdf. Update the Status column (J) as you build; this sheet counts it.
A4: By area | B4: Screens | C4: In prototype
A5: Public | B5: =COUNTIF(Screens!$B$2:$B$51,A5) -> 17 | C5: =COUNTIFS(Screens!$B$2:$B$51,A5,Screens!$G$2:$G$51,"Yes*") -> 17
A6: Patient | B6: =COUNTIF(Screens!$B$2:$B$51,A6) -> 11 | C6: =COUNTIFS(Screens!$B$2:$B$51,A6,Screens!$G$2:$G$51,"Yes*") -> 11
A7: Professional | B7: =COUNTIF(Screens!$B$2:$B$51,A7) -> 8 | C7: =COUNTIFS(Screens!$B$2:$B$51,A7,Screens!$G$2:$G$51,"Yes*") -> 7
A8: Admin | B8: =COUNTIF(Screens!$B$2:$B$51,A8) -> 11 | C8: =COUNTIFS(Screens!$B$2:$B$51,A8,Screens!$G$2:$G$51,"Yes*") -> 10
A9: Supporting | B9: =COUNTIF(Screens!$B$2:$B$51,A9) -> 3 | C9: =COUNTIFS(Screens!$B$2:$B$51,A9,Screens!$G$2:$G$51,"Yes*") -> 2
A10: Total | B10: =SUM(B5:B9) -> 50 | C10: =SUM(C5:C9) -> 47
A12: By status | B12: Screens
A13: Not started | B13: =COUNTIF(Screens!$J$2:$J$51,A13) -> 50
A14: Designing | B14: =COUNTIF(Screens!$J$2:$J$51,A14) -> 0
A15: In prototype | B15: =COUNTIF(Screens!$J$2:$J$51,A15) -> 0
A16: Approved | B16: =COUNTIF(Screens!$J$2:$J$51,A16) -> 0
A17: Building | B17: =COUNTIF(Screens!$J$2:$J$51,A17) -> 0
A18: Built | B18: =COUNTIF(Screens!$J$2:$J$51,A18) -> 0
A19: Tested | B19: =COUNTIF(Screens!$J$2:$J$51,A19) -> 0
A22: By build milestone | B22: Screens
A23: M1 (19 to 23 Oct) | B23: =COUNTIF(Screens!$H$2:$H$51,"M1*") -> 2
A24: M2 (26 Oct to 13 Nov) | B24: =COUNTIF(Screens!$H$2:$H$51,"M2*") -> 27
A25: M3 (9 to 27 Nov) | B25: =COUNTIF(Screens!$H$2:$H$51,"M3*") -> 18
A26: M4 (30 Nov to 4 Dec) | B26: =COUNTIF(Screens!$H$2:$H$51,"M4*") -> 1
A27: January batch | B27: =COUNTIF(Screens!$H$2:$H$51,"January*") -> 2
A29: Note: Introduction inbox counts under M2 (placeholder) and is finished in M3; email templates count under M2.
A31: Rules by evidence type | B31: Rules
A32: research | B32: =COUNTIF(Rules!$G$2:$G$157,A32) -> 93
A33: guideline | B33: =COUNTIF(Rules!$G$2:$G$157,A33) -> 30
A34: practitioner | B34: =COUNTIF(Rules!$G$2:$G$157,A34) -> 24
A35: law | B35: =COUNTIF(Rules!$G$2:$G$157,A35) -> 9
A36: Total | B36: =SUM(B32:B35) -> 156
A38: Legend
A39: Edit only the Status column (J) on the Screens sheet; everything else is the plan. Row colours mark the area. Type colours on the Rules sheet: research (aqua), guideline (blue), practitioner (sand), law (gold, verify with counsel).

Sheet Screens
A1: # | B1: Area | C1: Screen | D1: Purpose | E1: States to design | F1: Data shown | G1: In prototype (23 Oct) | H1: Real build | I1: Task ref | J1: Status | K1: Notes | L1: Design pointers (19 Oct research) | M1: Rule refs | N1: Layout call (judgement, phone first)
A2: 1 | B2: Public | C2: Home | D2: Land, search, trust | E2: Default; search typed; intake chat open | F2: Hero copy, search box, specialty chips, 1 to 2 verified doctors, 3 steps | G2: Yes | H2: M2 | I2: 1.6, 2.1 | J2: Not started | K2: Lagoon hero per approved board; featured carousel moves to January | L2: 1. First screenful: tagline that names the buyer (US-trained, Arabic-speaking doctors for you), search box, one CTA. In Arabic the CTA and headline sit top-right. 2. Trust strip above any counts: Licence verified, US board certified (one-sentence definition on first appearance), price from X. Lead with US training. 3. Real doctor photos only (no stock); conservative dress, both genders. Show counts only if large; otherwise show two verified doctors instead of a number. 4. Up to 4 visible nav links on mobile; language switch in the header as العربية / English with a globe, no flags. 5. One line: not for emergencies, with the viewer's local emergency number; a short how a US doctor can see you section or link (41.9% of Saudi users unclear on legality). 6. No false floor after the hero; LCP 2.5 s on mobile (compress photos, water effect must not block paint); content-shaped skeleton for the doctor strip. | M2: G2 H1 H2 H4 H5 H6 H7 H8 H10 H11 H12 H13 H14 H15 L1 R9 | N2: Lagoon hero (approved board) with headline, one-line sub, search box with specialty autocomplete, four specialty chips. Then a trust strip (Licence verified, US board certified with tooltip, visit from USD X). Then two verified doctor cards, three steps, FAQ teaser, footer with address. Above the fold: headline, search, chips. Hook: the search box returns live suggestions as you type.
A3: 2 | B3: Public | C3: Why US training | D3: Explain the value of US-trained doctors | E3: Default | F3: Copy from content document | G3: Yes | H3: M2 | I3: 1.6 | J3: Not started | L3: 1. Grade-6 copy, single column, main message in the first paragraph; front-load headings. 2. Link every credential claim to ABMS Certification Matters or the state board; define board certified; last-reviewed date at the bottom. 3. Use the medical-tourism fact (USA is Saudi's top destination) as the bridge; explain how the visit works legally in one paragraph. | M3: H3 H8 H13 H15 X1 X2 X3 X4 | N3: Single column: title, one-paragraph answer, then three short sections (what US training means, how we verify, what it costs you), each with a link to the verifier. Sidebar on desktop holds the three-credential strip. Above the fold: the one-paragraph answer. Hook: a Check a doctor link into the directory.
A4: 3 | B4: Public | C4: How it works | D4: Patient journey in 3 steps | E4: Default | F4: Steps, fees explained, visit types | G4: Yes | H4: M2 | I4: 1.6 | J4: Not started | L4: 1. Three steps, two levels of detail at most, recommended path highlighted; make clear no account is needed to browse. 2. Explain fees as one all-in number plus what it includes; cancellation terms here too; video vs phone with a best-for line. 3. What to prepare for a visit (device test, private room, ID) and the not-for-emergencies line. | M4: C5 C12 F9 H14 P5 P10 X5 X6 | N4: Three numbered steps as stacked cards (find, book, talk), each with one line and a small illustration; fees box under step 2; visit types under step 3; what to prepare as an accordion; CTA to search at the end and sticky on phone. Above the fold: step 1 and 2. Hook: fee example with the three lines filled in.
A5: 4 | B5: Public | C5: Specialty directory | D5: Browse 104 groups | E5: Default; empty group | F5: 104 groups, Arabic and English names, doctor counts | G5: Yes | H5: M2 | I5: 2.1 | J5: Not started | K5: Counts show verified only | L5: 1. Curated top specialties first with see all 104; names Arabic first with English in parentheses. 2. Counts per group (verified only); hide groups with zero bookable doctors from promotion rather than showing 0. 3. Grid is fine here (heterogeneous browse); in Arabic the first item is top-right. | M5: H6 R9 S10 S14 S16 S17 X7 | N5: Six curated specialties as large tiles, then See all 104 expands an alphabetical two-column list grouped by body system, Arabic first with English small. Count badge on each. Above the fold: the six tiles and the search box. Hook: tiles show one doctor photo each.
A6: 5 | B6: Public | C6: Search results | D6: Find a doctor by filters | E6: Results; empty; loading skeleton | F6: Filters: specialty, language, location, visit type, age group; DoctorCard list; pagination | G6: Yes | H6: M2 | I6: 2.1 | J6: Not started | K6: Verified only, featured first, 20 per page | L6: 1. One doctor per row, same attribute set in the same order; key data at the reading-start corner. 2. Replace pagination with Load more (15 to 30 mobile, 25 to 75 desktop); filter state in the URL; restore scroll on Back. 3. Default sort Relevance, verified above unclaimed; any paid placement carries a Sponsored label on the card itself. 4. Add gender, price and next-available-72h to the filters; counts per option; mobile bottom sheet with Show N doctors; applied chips with Clear all; truncate long lists at 6 to 10. 5. Autocomplete capped at 10/8; transliteration and typo tolerance; symptom words map to specialties. 6. Zero results: relaxed scope, 3 to 5 alternatives, popular doctors, WhatsApp/contact; skeleton shaped like rows. | M6: A4 C1 C2 L1 L3 R9 S1 S2 S3 S4 S5 S6 S7 S8 S9 S10 S11 S12 S13 S14 U3 | N6: Sticky top bar: query, Filters button with count, sort. Applied-filter chips row. One doctor per row: photo left (right in RTL), name and specialty, languages, next available, all-in price, Book. Load more after 20 on phone. Desktop: filters in a left column, list right. Above the fold: first two rows. Hook: next available slot on every row.
A7: 6 | B7: Public | C7: Doctor profile: unclaimed | D7: Public registry listing | E7: Default; removal pending | F7: Name, specialty, city, medical school, graduation year, group, hospital; registry label; Invite; This is me | G7: Yes | H7: M2 | I7: 2.2 | J7: Not started | K7: No fee, availability, checkout or contact (tested) | L7: 1. Banner: Unclaimed, from public US records (source, date), not confirmed by the doctor. Facts only, no score or stars; neutral specialty placeholder photo. 2. Are you Dr X? Claim this profile, free (preview of what they can edit) plus This is not me / remove link. 3. No Book, no fee, no availability (as planned); offer Find a verified doctor in this specialty so the patient is not stranded. | M7: C3 S6 U1 U2 U3 U4 U5 | N7: Grey Unclaimed banner with source and date at the top. Placeholder photo, name, specialty, city. Facts table (school, year, group, hospital). Then a teal panel: Are you Dr X? Claim this profile, free. Then Find a verified doctor in this specialty. Above the fold: banner, name, claim panel. Hook: claim panel shows the finished card they would get.
A8: 7 | B8: Public | C8: Doctor profile: verified | D8: Book a first visit | E8: Default; no availability; payouts not ready (book hidden) | F8: Card front and back data, bio, training, languages, fees, visit types, ages, tags, availability preview, verified date, Book | G8: Yes | H8: M2 | I8: 2.2 | J8: Not started | K8: Book button needs Stripe Connect enabled (M3) | L8: 1. Block order: card, credentials (board named, verified on date, link to verifier), fees and visit types, availability, bio. Define board certified on first use. 2. All-in price and next available above the fold; sticky Book on mobile; Accepting new patients state. 3. No reviews at launch: show years in practice and training as the trust signal and a New to 3affya label; no scarcity tricks. 4. Video vs phone with a best-for line (see Q1 for Saudi); cancellation terms near Book; English bio stays left-aligned inside the Arabic page. | M8: C5 C6 C7 C8 C9 C10 C11 C12 H8 P5 R4 X3 | N8: Card front as the header (photo, names, specialty, city, verified badge with date). Then fee and next three slots with a sticky Book bar on phone. Then credentials and training, languages and visit types, bio, availability preview. Desktop: card and booking box pinned right, content left. Above the fold: card, fee, next slots. Hook: tap the card to flip to the back.
A9: 8 | B9: Public | C9: Intake chat | D9: Suggest a specialty, prefill introduction request | E9: Consent; questions; result; fallback form; model error | F9: Concern, age group, language, visit type; 1 to 3 suggested specialties with doctors | G9: Yes (static) | H9: M3 | I9: 3.12 | J9: Not started | K9: Light version of agent 12; no medical advice | L9: 1. Opening message: AI assistant, not a doctor, not a diagnosis, what it can do, local emergency number, Talk to a human always visible. 2. Quick replies for concern, age group, language, visit type; no date of birth or card in chat; back and I did not understand supported. 3. Output is 1 to 3 specialties with doctors, never a diagnosis or triage level; red-flag keywords end intake with emergency guidance. 4. Consent line before the first question; typing indicator under 1 s, step text if a reply takes longer. | M9: H14 I1 I2 I3 I4 I5 L1 Q6 T3 | N9: Full-height sheet over the page on phone, right-side panel on desktop. Bot message with scope, emergency line and Talk to a human pinned at the top. Quick-reply chips under each question; free-text box at the bottom. Result: three specialty cards each with two doctors. Above the fold: first question and chips. Hook: the result cards link straight to filtered search.
A10: 9 | B10: Public | C10: Claim invite landing | D10: Doctor opens invite link | E10: Valid token; expired; used; forged | F10: Pre-filled name and specialty; OTP sign-up; request new invite | G10: Yes | H10: M2 | I10: 2.3 | J10: Not started | K10: Rate limited 10 per IP per hour | L10: 1. Show the pre-built profile first (name, specialty from registry), then OTP; promise you can always edit this; checklist starts partly filled. 2. OTP single field, numeric keyboard, paste works; Open Gmail link; rate-limit, do not reveal whether the email exists. 3. Visible This is not me; one line that claiming means patients will see you, so keep availability current. | M10: B1 B3 F6 F7 U4 U5 U6 W4 | N10: Centred single column: the pre-built card at the top (name, specialty from registry), one sentence of what claiming gives, email field pre-filled, Send code button, then the six-digit field. Expired or used token shows the same card with Request a new link. Above the fold: card and email field. Hook: the card is already theirs.
A11: 10 | B11: Public | C11: This is me / remove me | D11: Doctor asks for removal or claims | E11: Form; submitted | F11: Name, NPI, email, reason | G11: Yes | H11: M2 | I11: 2.2, 2.8 | J11: Not started | K11: 48 hour admin SLA | L11: 1. Four fields, labels above, specific errors; NPI field LTR numeric. 2. Submitted state names the 48-hour SLA and what happens next (410 within 48 hours). | M11: A3 F1 F2 F5 U4 | N11: Short centred form: two radio choices (This is me, Remove me) that change the copy, then name, NPI, email, reason. Submitted state: what happens and the 48-hour promise. Above the fold: the whole form. Hook: none needed; keep it under one screen.
A12: 11 | B12: Public | C12: AI tools (coming soon) | D12: Tease agents 2 to 11 | E12: Default | F12: Agent names and one line each | G12: Yes | H12: M2 | I12: 1.6 | J12: Not started | K12: No pricing shown | L12: 1. One plain line per agent, front-loaded; no pricing. 2. Say every AI output will be labelled and reviewed; not a diagnosis. | M12: H3 T4 T5 X1 | N12: Title, one line of intent, then a two-column list of ten agents with name and one line each, muted style. One CTA: Tell me when these launch (email). Above the fold: title and first four. Hook: the notify field.
A13: 12 | B13: Public | C13: For professionals | D13: Explain membership and claim flow | E13: Default | F13: Membership tiers (prices from Q8), banner add-on, how claiming works | G13: Yes | H13: M2 | I13: 1.6 | J13: Not started | K13: Prices placeholder until 7 Nov | L13: 1. Three tiers, at most four differing attributes, all-in price and billing period, static comparison table (prices placeholder until 7 Nov). 2. Sell on numbers: live availability (half of new patients book within 72 h), photo (2x views); show the practice card as the reward. 3. How claiming works: free, from your registry profile, only verifiable fields required; note that patients will scrutinise a claimed profile. | M13: B2 B4 B8 B9 C5 U5 U6 | N13: Hero line for doctors, then the practice card shown large as the reward, then three steps (claim, verify, go live), then a three-column tier table (stacked on phone, middle tier highlighted), then FAQ for doctors. Above the fold: hero and card. Hook: Find your profile search box in the hero.
A14: 13 | B14: Public | C14: FAQ | D14: Common questions | E14: Default | F14: Q and A from content document | G14: Yes | H14: M2 | I14: 1.6 | J14: Not started | L14: 1. Grade-6 answers, accordion, two levels; include How can a US doctor see me? and What this visit cannot do. 2. Fees, refunds and how records are processed (AI consent, where stored) answered here too. 3. Last-reviewed date. | M14: C5 H15 P5 T3 X1 X4 X5 | N14: Search-within-FAQ field, then grouped accordions (For patients, Fees and refunds, Records and AI, For doctors). Each answer under six lines. Last-reviewed date at the bottom. Above the fold: search field and first group. Hook: the search field.
A15: 14 | B15: Public | C15: About | D15: Who 3affya is | E15: Default | F15: Copy from content document | G15: Yes | H15: M2 | I15: 1.6 | J15: Not started | L15: 1. Operating entity, address, contact; real team and doctor photos. 2. Last-reviewed date; link to how verification works. | M15: G2 H4 H9 X3 X4 | N15: Single column: who 3affya is in two paragraphs, Dr Ayman photo and one-line bio, how verification works, entity and address, contact. Above the fold: the two paragraphs and photo. Hook: the verification explainer link.
A16: 15 | B16: Public | C16: Contact | D16: Reach 3affya | E16: Form; sent | F16: Name, email, message | G16: Yes | H16: M2 | I16: 1.6 | J16: Not started | K16: Sends via Resend | L16: 1. WhatsApp click-to-chat first, then email form; address shown. 2. Labels above, specific errors; sent state says when to expect a reply. | M16: F1 F5 G3 H9 L4 | N16: Two stacked choices: WhatsApp button first, then the three-field email form. Address and hours under it. Above the fold: both choices. Hook: WhatsApp opens with a pre-filled greeting.
A17: 16 | B17: Public | C17: Legal pages (4) | D17: Privacy, terms, fees, refunds | E17: Default | F17: Legal copy for Dr Ayman's lawyer | G17: Yes | H17: M4 | I17: 1.6, 4.3 | J17: Not started | K17: One template, four pages, both languages | L17: 1. Privacy page doubles as the Notice of Privacy Practices: prominent, plain language, effective date, complaints contact. 2. Counsel must settle: cross-border consult framing (Saudi supervision and video rule), UAE data residency, retention and deletion wording. 3. Fees and refunds page: the three lines, capture in full, refund not void, written estimate kept in the portal. | M17: P5 P15 Q1 Q2 Q3 Q4 T8 T9 X4 | N17: One template: title, effective date, a four-line plain summary box at the top, then numbered sections with a sticky in-page contents on desktop. Above the fold: the summary box. Hook: the summary box.
A18: 17 | B18: Public | C18: 404 and 410 | D18: Missing or removed pages | E18: 404; 410 removed profile | F18: Message, search box | G18: Yes | H18: M2 | I18: 2.2 | J18: Not started | K18: 410 for removed doctors | L18: 1. Search box plus popular specialties and a contact path; 410 explains the doctor was removed at their request and offers the specialty search. | M18: L4 S6 | N18: Centred: short message, search box, four specialty chips, contact link. 410 adds one line that the doctor asked to be removed. Above the fold: everything.
A19: 18 | B19: Patient | C19: Sign up and login | D19: OTP by email | E19: Enter email; enter code; error; rate limited | F19: Email, 6 digit code | G19: Yes | H19: M3 | I19: 3.6 | J19: Not started | L19: 1. One OTP field, inputmode numeric, autocomplete one-time-code, paste works, 16 px input; email keyboard, autocorrect off. 2. Open Gmail link; sign-in asked only at booking or upload, never to browse. 3. Rate-limited state says when to retry; errors in text next to the field. | M19: F5 F6 F7 F8 F9 L4 W4 | N19: Centred card: one email field and Continue; second step replaces it with one six-digit field, Open Gmail link, resend timer. Why we ask line under the field. Above the fold: the whole card.
A20: 19 | B20: Patient | C20: Slot picker | D20: Choose a time in the patient's timezone | E20: Slots; no slots this week; hold started | F20: Doctor card, calendar, slots converted to viewer timezone, visit type | G20: Yes | H20: M3 | I20: 3.2 | J20: Not started | K20: DST tests across Riyadh, Dubai, London | L20: 1. Patient zone named on every slot, doctor time secondary; Western digits forced; weekends shaded per the patient's country. 2. 48 px slot buttons; hold starts within 400 ms; calendar chevrons mirrored in RTL, clock icon not. 3. Ask visit reason, age group and for whom before the hold; visit type choice with best-for line. 4. No slots this week: show next available week and a Request a time path, never an empty grid. | M20: C12 L2 L3 N1 P6 P7 P8 R2 S6 W2 | N20: Mini doctor card at the top, visit-type segmented control, week strip (swipe), slot grid of 48 px buttons in the patient zone with the zone named, doctor time in small text on the selected slot. Reason, age group and for whom appear after a slot is picked. Sticky Continue. Above the fold: card, visit type, this week's slots. Hook: the next available slot is pre-highlighted.
A21: 20 | B21: Patient | C21: Checkout | D21: Pay for the first visit | E21: Hold timer running; hold expired; payment failed; success | F21: Doctor fee, platform fee, card processing as 3 lines; total; Stripe element | G21: Yes | H21: M3 | I21: 3.2, 3.3 | J21: Not started | K21: 10 minute hold; lines sum to intent to the cent | L21: 1. Three lines sum to the total, nothing new; Review with edit links, then a distinct Confirmation. 2. Card fields in a bordered box with Secured by Stripe; Apple Pay and Google Pay first; expiry MM / YY; capture in full; keep details after an error. 3. Cancellation terms and telehealth consent on this step; confidentiality line in plain Arabic. 4. Local currency, three decimals for KWD/OMR/BHD, Western digits, currency sign part of the number. 5. Backup phone and country; no re-asking of data from the slot picker. 6. Hold timer visible; paying state shows steps, never a blank spinner. | M21: C5 F2 F10 L1 N1 N2 P1 P2 P3 P4 P5 P9 P12 P13 P14 T11 T12 | N21: Single page, two blocks: Review (doctor, time in both zones, visit type, edit links) and Pay (three lines and total, then the card box with Apple Pay and Google Pay buttons above the card fields). Consent and cancellation checkboxes between the blocks. Hold timer in the sticky header. Confirmation is a separate page. Above the fold: review block and total. Hook: the hold timer.
A22: 21 | B22: Patient | C22: Booking confirmation | D22: Show what was booked | E22: Default | F22: Time in both timezones, video link, .ics, receipt link, share records prompt | G22: Yes | H22: M3 | I22: 3.3 | J22: Not started | L22: 1. Peak-end: both times with zones, join link, add to calendar, what to prepare, how to change, expected lead time. 2. One-tap device check link; not-for-emergencies line with local number. 3. Share records prompt explains AI consent and who will see them. | M22: G4 H14 P6 P10 T3 T7 | N22: Green check and one line, then the appointment card (time in both zones, join link), Add to calendar, then a three-item prepare checklist with Test your device, then Share records prompt, then receipt link. Above the fold: card and calendar button. Hook: Test your device.
A23: 22 | B23: Patient | C23: Bookings list | D23: See past and upcoming visits | E23: List; empty | F23: Status (upcoming, done, cancelled, refunded), doctor, time | G23: Yes | H23: M3 | I23: 3.6 | J23: Not started | L23: 1. Empty state: what it is, why empty, Find a doctor action; view is the primary action. 2. Times in the patient zone; cancel uses outcome-named buttons (Cancel booking / Keep booking). | M23: B10 L3 P6 T1 | N23: Tabs Upcoming and Past. Each row: doctor photo, date and time in the patient zone, status chip, Join or View. Empty state with Find a doctor. Above the fold: next visit as a larger card, then the list.
A24: 23 | B24: Patient | C24: Receipts | D24: Itemised receipts | E24: List; detail; refund line | F24: Lines, totals, refund entries | G24: Yes | H24: M3 | I24: 3.6 | J24: Not started | L24: 1. Total prominent, three lines, last 4 digits, both times, refund entries; written estimate retained; local currency. | M24: E3 P14 P15 | N24: List of rows (date, doctor, total, status). Detail: total large, the three lines, refund entries below, download PDF. Above the fold: the list.
A25: 24 | B25: Patient | C25: Records upload | D25: Upload files, get a quote | E25: Dropzone; validating; rejected files listed; quote; consent; paying | F25: Files, accepted size, pages, quote in 1 GB blocks (USD 9.99 each), consent checkbox | G25: Yes | H25: M3 | I25: 3.7 | J25: Not started | K25: Nothing processes before payment | L25: 1. Separate AI-processing consent checkbox with a where your data is stored line; UAE residency to be settled (Q3). 2. Phone photos first (camera button), formats and size visible, per-file success or specific rejection reason. 3. Quote shown as one all-in number before consent; nothing processes before payment (as planned). | M25: C5 F8 L4 P1 Q3 T3 T10 | N25: Dropzone with a camera button first on phone. Below it the file list with per-file status. Then the quote box (files, pages, total). Then the two consent checkboxes (privacy, AI processing with the where-stored line) and Pay. Above the fold: dropzone and file list. Hook: the quote updates as files land.
A26: 25 | B26: Patient | C26: Records processing | D26: Show progress | E26: Queued; per page progress; failed with reason; done | F26: File list, pages done of total, cost so far | G26: Yes | H26: M3 | I26: 3.8 | J26: Not started | K26: Standing rule: never a blank wait | L26: 1. Live step list with page counts and cost so far; estimate and cancel when over 10 s; no fake percentage. 2. Failed state names the reason and the fix (re-upload page 4). | M26: L1 L3 L4 T11 | N26: One card: overall status line, then a step list with the current step live (page 4 of 12), cost so far, estimate, Cancel. Below: what you will get, as three lines. Above the fold: everything. Hook: the step list moving.
A27: 26 | B27: Patient | C27: Summary and timeline | D27: Read the one page summary | E27: Overview; timeline; flags; source page open | F27: Diagnoses, procedures, medications, allergies, results with page links; missing and conflict flags; unreadable flags | G27: Yes | H27: M3 | I27: 3.9, 3.10 | J27: Not started | L27: 1. AI-generated label at the top, Reviewed by Dr X or Not yet reviewed, Talk to a human; not-a-diagnosis in the body. 2. Release immediately with a framing line; every statement links to its source page; explain each number; something missing? link. 3. Timeline numerals LTR with mirrored axis in Arabic; download is a primary action. | M27: Q6 R11 T1 T2 T4 T5 T6 X1 | N27: AI-generated label and reviewed state at the top, Talk to a human beside it. Tabs Overview, Timeline, Flags. Overview: five blocks (diagnoses, procedures, medications, allergies, results), each item with a source-page link opening a side viewer (sheet on phone). Timeline is vertical on phone. Above the fold: label and first two blocks. Hook: tap any item to see the source page.
A28: 27 | B28: Patient | C28: Sharing and consent | D28: Share with one doctor | E28: No shares; shared (expiry); revoked | F28: Chosen professional, expiry date, revoke | G28: Yes | H28: M3 | I28: 3.10 | J28: Not started | K28: Default 30 days until Q13 | L28: 1. Who can see this panel, expiry visible, revoke in one tap; plain confidentiality line. 2. No shares: explain what sharing does and offer Share with your booked doctor. | M28: L3 T7 T12 | N28: List of shares as rows (doctor, expires on, Revoke). Share with a doctor button opens a sheet listing booked doctors and an expiry picker. Who can see this panel pinned at the top. Above the fold: panel and first share.
A29: 28 | B29: Patient | C29: Settings | D29: Language, timezone, delete account | E29: Default; delete confirm | F29: Locale, IANA timezone, delete | G29: Yes | H29: M3 | I29: 3.6 | J29: Not started | L29: 1. Delete explains what is removed and what retention keeps; confirmation buttons name the outcome. 2. Timezone from a GCC-first list; Gregorian with optional Hijri; language in its own script. | M29: B10 H10 N3 P6 T8 | N29: Grouped list: Language, Timezone, Calendar (Gregorian, Hijri on), Notifications, then a Danger section with Delete uploads and Delete account, each explaining retention. Above the fold: first two groups.
A30: 29 | B30: Professional | C30: Profile builder | D30: Claim, onboard, edit, see the card live | E30: Pre-filled from registry; editing; credentials uploaded (pending); submitted for review; rejected with reason; live | F30: Photo, names (en, ar), specialty, city and state, languages and dialect, visit types and fees, ages, video link, training, bio (en, ar), up to 10 expertise tags, credential uploads, publish checklist, live DoctorCard front and back, Arabic preview | G30: Yes | H30: M2 | I30: 2.4, 2.5 | J30: Not started | K30: ikioo flow restyled; replaces 5 screens; phone layout with sticky mini card | L30: 1. Opens pre-filled from registry; required = NPI, licence, board, specialty, photo; checklist starts partly filled with steps remaining. 2. Live card is the reward; photo step says profiles with photos get about 2x views. 3. Photo guidance: white coat, plain background, no group or stock; reject obvious stock. 4. Structured fields: years in practice, board and status (board eligible is text, not badge), training, languages with dialect, Accepting (off until availability set). 5. Labels above, chunks of 4 to 6, validate on blur, specific errors; Arabic fields budget 30% more width. 6. Arabic preview aligns English bio by its language; NPI and phone stay LTR. | M30: B1 B2 B3 B4 B5 B6 B7 C3 C4 F1 F3 F4 F5 G2 R3 R4 R8 S16 | N30: Phone: form sections stacked with a sticky mini card at the top that updates live; tap it to see the full card and flip. Desktop: form left, full card right, pinned. Section order: photo, names, specialty and city, languages, visit types and fees, training and credentials, bio, tags, availability link, publish checklist. Progress bar under the header starts part-filled. Above the fold: mini card, photo step. Hook: the card changing as you type.
A31: 30 | B31: Professional | C31: Availability editor | D31: Weekly rules, exceptions, timezone | E31: Default; exception added; preview as Riyadh viewer | F31: Weekly rules, date exceptions, slot length, IANA timezone | G31: Yes | H31: M2 | I31: 2.6 | J31: Not started | L31: 1. Weekend shading follows the preview country; Riyadh preview shows zone and no-DST note; Gregorian. 2. Changes apply within 400 ms with undo, no confirmation dialogs. 3. Saving the first rule flips Accepting new patients on, with a one-line notice. | M31: B6 B10 L2 N3 P6 P7 | N31: Weekly grid (seven columns, swipeable on phone) with tap-to-add rules, exceptions list below, slot length and timezone selectors above. Preview as Riyadh viewer toggle shows the patient's view. Above the fold: the week grid. Hook: the preview toggle.
A32: 31 | B32: Professional | C32: Practice ID card | D32: View and download the card | E32: Front; back; unverified watermark | F32: Card PNG in both languages | G32: Yes | H32: M2 | I32: 2.7 | J32: Not started | K32: Same DoctorCard component rendered to PNG | L32: 1. Verification tick and logo never mirrored; Arabic +2 pt, letter-spacing 0, real weights. 2. Badge text: Credentials verified on [date]; unverified watermark until approved. | M32: A2 C8 R2 R5 R6 | N32: Card shown large, flip button, language toggle, Download PNG for each side. Unverified watermark until approved. Above the fold: the card.
A33: 32 | B33: Professional | C33: Introduction inbox | D33: See bookings and requests | E33: Empty; list; detail with shared summary link | F33: Booking time, patient first name, video link, shared summary | G33: Yes | H33: M2 (placeholder), M3 (real) | I33: 2.9, 3.3 | J33: Not started | L33: 1. Empty state explains when requests appear; detail answers what, when (both zones), how to join. 2. Shared summary link shows expiry and that the patient can revoke. | M33: E2 L3 T7 | N33: Rows: patient first name, date and time in the doctor zone, status, Join. Detail drawer: both times, join link, shared summary link with expiry. Above the fold: next visit large, then the list.
A34: 33 | B34: Professional | C34: Membership and billing | D34: Subscribe and manage | E34: No membership; active; past due (grace); cancelled | F34: Tier, renewal date, Stripe Customer Portal link | G34: Yes | H34: M3 | I34: 3.5 | J34: Not started | K34: Stripe hosted checkout and portal | L34: 1. Tier, all-in price, renewal date; past-due state says the grace period and what stops. 2. Cancel via Stripe portal; confirmation names the outcome. | M34: B8 B10 C5 | N34: Current tier card (name, price, renewal), then Manage billing (Stripe portal), then the tier table for upgrades. Past due shows a gold banner at the top. Above the fold: tier card.
A35: 34 | B35: Professional | C35: Featured banner | D35: Buy the carousel slot | E35: Hidden until carousel ships | F35: Price, status | G35: No | H35: January | I35: 3.5 | J35: Not started | K35: Carousel moved to January | L35: 1. Any purchased slot renders with a Sponsored label at the reading-start corner, shaded; same attributes as organic cards. | M35: A4 | N35: Hidden until January. When shown: price, dates picker, preview of the home carousel slot with the Sponsored label visible in the preview.
A36: 35 | B36: Professional | C36: Payouts setup | D36: Connect Stripe Express | E36: Not started; in progress; enabled; restricted | F36: Stripe onboarding link, charges and payouts enabled flags | G36: Yes | H36: M3 | I36: 3.1 | J36: Not started | K36: Book button hidden until enabled | L36: 1. Show the claimed card and expected earnings before the Stripe link; state the steps and that they can resume. 2. Restricted state names what Stripe needs. | M36: B3 B5 F3 L3 | N36: One card: the doctor's practice card small, a sentence on how payouts work, three-step status list (identity, bank, enabled), the Stripe button. Restricted state lists what Stripe needs. Above the fold: everything.
A37: 36 | B37: Professional | C37: Shared summaries | D37: Read what patients shared | E37: Empty; list; viewer | F37: Summaries shared with this professional, expiry | G37: Yes | H37: M3 | I37: 3.10 | J37: Not started | L37: 1. AI label and reviewed state carry through; expiry shown. | M37: T4 T7 | N37: Rows: patient first name, shared on, expires on, Open. Viewer reuses the patient summary screen with the AI label and reviewed state. Above the fold: the list.
A38: 37 | B38: Admin | C38: Login with TOTP | D38: Secure admin access | E38: Email; code; TOTP; refused | F38: Email, OTP, TOTP | G38: Yes | H38: M2 | I38: 2.8 | J38: Not started | K38: No TOTP, no access (tested) | L38: 1. Single-field codes, paste works, errors in text; refused state gives no hint which factor failed. | M38: F5 F6 W4 | N38: Centred card, three sequential steps replacing each other: email, code, authenticator code. No branding beyond the wordmark. Above the fold: the card.
A39: 38 | B39: Admin | C39: Credential review queue | D39: Approve or reject claims | E39: Queue; detail with documents; approved; rejected with reason | F39: Claim, uploads, registry data, decision, reason | G39: Yes | H39: M2 | I39: 2.8 | J39: Not started | K39: Approve sets verified plus date | L39: 1. Checklist per claim: licence (state board), board (ABMS), sanctions (FSMB/NPDB); store source, date, reviewer; board eligible never becomes the badge. 2. Photo check (white coat, no stock); approve/reject with outcome-named buttons; reject requires a reason the doctor sees. | M39: A1 A2 B7 B10 C4 | N39: Left: queue list with age and status. Right: detail with the registry data and the doctor's entries side by side, documents as thumbnails opening in a viewer, a verification checklist (licence, board, sanctions, photo) each with source and date fields, then Approve or Reject with reason. Above the fold: the checklist.
A40: 39 | B40: Admin | C40: Listings | D40: Manage professionals | E40: Table with status filter; edit | F40: Status (unclaimed, claimed, verified, rejected, removed), specialty, city | G40: Yes | H40: M2 | I40: 2.8 | J40: Not started | L40: 1. Verified-on date and next re-verification column; unclaimed clearly distinct. | M40: A2 A5 U1 | N40: Table with status filter chips above (Unclaimed, Claimed, Verified, Rejected, Removed), columns name, specialty, city, verified on, next re-verification; row click opens an edit drawer.
...

Sheet Rules
A1: ID | B1: Group | C1: Rule | D1: Applies to | E1: Evidence | F1: Source | G1: Type | H1: URL
A2: H1 | B2: Home and marketing pages | C2: Put the value proposition, the differentiator and the primary CTA in the first screenful, and signal that more follows. | D2: Home, explainer, directory landing | E2: 57% of viewing time is above the fold, 74% in the first two screenfuls (NN/g eyetracking 2018). | F2: NN/g, Scrolling and Attention | G2: research | H2: https://www.nngroup.com/articles/scrolling-and-attention/
A3: H2 | B3: Home and marketing pages | C3: Write a one-line tagline that says what the site does and for whom; never a generic welcome. | D3: Home | E3: Homepage must work as an elevator pitch; vague labels have weak information scent. | F3: NN/g, Homepage Design Principles | G3: research | H3: https://www.nngroup.com/articles/homepage-design-principles/
A4: H3 | B4: Home and marketing pages | C4: Front-load the first two words of every heading, bullet and paragraph with information-carrying words. | D4: All content | E4: F-pattern eyetracking of 232 users: readers catch the first two words of a line far more than the third. | F4: NN/g, F-Shaped Pattern | G4: research | H4: https://www.nngroup.com/articles/f-shaped-pattern-reading-web-content-discovered/
A5: H4 | B5: Home and marketing pages | C5: Use real photos of the actual doctors and team; never stock people or decorative hero figures. | D5: Home, about, cards, profiles | E5: Users spent 10% more time on real team portraits than on bios taking 316% more space; stock people are ignored as filler. | F5: NN/g, Photos as Web Content | G5: research | H5: https://www.nngroup.com/articles/photos-as-web-content/
A6: H5 | B6: Home and marketing pages | C6: Show up to 4 top-level links visibly on mobile before hiding the rest; keep visible nav on desktop. | D6: All pages | E6: Hidden nav: discoverability down 20%+, tasks 39% slower on desktop and 15% on mobile (n=179). | F6: NN/g, Hamburger Menus | G6: research | H6: https://www.nngroup.com/articles/hamburger-menus/
A7: H6 | B7: Home and marketing pages | C7: Show counts (doctors, specialties, bookings) only when they are large enough to impress; small numbers backfire. | D7: Home, directory | E7: A participant judged an article unpopular because it had only 1,000 shares. | F7: NN/g, Social Proof in the UX | G7: research | H7: https://www.nngroup.com/articles/social-proof-ux/
A8: H7 | B8: Home and marketing pages | C8: Put the three most-trusted credentials (licence, board certification, price) above the fold, ahead of any reviews. | D8: Home, profile | E8: Licence, board certification and insurance/price rated most important when choosing a clinician; reviews rated least. | F8: J Patient Exp 2022, Choosing a Provider | G8: research | H8: https://doaj.org/article/30019e7bdeea4028b38558d51565cb57
A9: H8 | B9: Home and marketing pages | C9: Define US board certified in one plain sentence wherever the badge first appears. | D9: Home, cards, profile, builder | E9: Only 23% of consumers could define board certification; 78% wrongly think it is required to practise; 91% rate it important once defined. | F9: ABMS 2010 Consumer Survey | G9: research | H9: https://www.abderm.org/media/40431/abms-2010-consumer-survey.pdf
A10: H9 | B10: Home and marketing pages | C10: Show a physical address, the operating entity, and an easy contact route on the home page and footer. | D10: Home, about, contact, footer | E10: Stanford credibility guidelines 2 and 5 (4,500+ participants). | F10: Stanford Web Credibility Guidelines | G10: research | H10: https://credibility.stanford.edu/guidelines
A11: H10 | B11: Home and marketing pages | C11: Language switcher in the header, each language in its own script (العربية / English), globe icon, never a flag. | D11: All pages | E11: W3C i18n: options in the target language, recognisable icon, keep on-page links even with auto-detect. | F11: W3C, Language selection | G11: guideline | H11: https://www.w3.org/International/questions/qa-navigation-select
A12: H11 | B12: Home and marketing pages | C12: Avoid false floors: never end a full-width section with a CTA and whitespace that looks like the page end. | D12: Home, explainer | E12: Illusion of completeness (NN/g); cut-off items and rhythm signal continuation (CXL). | F12: NN/g Illusion of Completeness; CXL False Bottom | G12: research | H12: https://www.nngroup.com/videos/illusion-completeness/
... A146: G6 | B146: Gulf audience: trust, payments, mobile | C146: No cash on delivery or BNPL at launch; cards plus wallets only. | D146: Checkout | E146: COD fell to about 10% in Saudi, UAE, Kuwait; BNPL about 4%; 85% of Saudi retail payments electronic in 2025. | F146: Gulf Business/Checkout.com 2024; SAMA | G146: practitioner | H146: https://www.sama.gov.sa/en-US/News/Pages/news-1139.aspx
A147: G7 | B147: Gulf audience: trust, payments, mobile | C147: Neutral respectful register (أهلاً بك); no scripted religious phrases in system copy; test with users. (No reliable source found; treat as a default.) | D147: All Arabic copy | E147: Gap in the research; practitioner default. | F147: None | G147: practitioner
A148: W1 | B148: Accessibility (WCAG 2.2) | C148: Text contrast 4.5:1 or more (3:1 for 24 px+); check gold on sand and white on lagoon. | D148: All screens, brand page | E148: WCAG 2.2 SC 1.4.3. | F148: W3C SC 1.4.3 | G148: guideline | H148: https://www.w3.org/WAI/WCAG22/Understanding/contrast-minimum.html
A149: W2 | B149: Accessibility (WCAG 2.2) | C149: Pointer targets at least 24x24 px; 48 px for primary mobile actions, slot buttons and chips. | D149: Slot picker, chips, icon buttons, chat quick replies | E149: WCAG 2.2 SC 2.5.8; Fitts's law; Digital.gov 48 px. | F149: W3C SC 2.5.8 | G149: guideline | H149: https://www.w3.org/WAI/WCAG22/Understanding/target-size-minimum.html
A150: W3 | B150: Accessibility (WCAG 2.2) | C150: Focus visible and never hidden by sticky headers, sticky CTAs or banners (scroll-padding). | D150: All screens | E150: WCAG 2.2 SC 2.4.7 and 2.4.11. | F150: W3C SC 2.4.11 | G150: guideline | H150: https://www.w3.org/WAI/WCAG22/Understanding/focus-not-obscured-minimum.html
A151: W4 | B151: Accessibility (WCAG 2.2) | C151: Never block paste or autofill on sign-in fields; label fields so password managers can fill them. | D151: Sign-in | E151: WCAG 2.2 SC 3.3.8. | F151: W3C SC 3.3.8 | G151: guideline | H151: https://www.w3.org/WAI/WCAG22/Understanding/accessible-authentication-minimum.html
A152: Q1 | B152: Regulatory items to settle with counsel | C152: Saudi: a practitioner outside the Kingdom may treat a patient inside it only under supervision of a KSA-based practitioner; teleconsultations must include video; the patient signs consent before the session; identity verified. Decide the product framing (second opinion, Saudi partner physician) with counsel. | D152: Scope, consent, visit types, legal pages | E152: Al Tamimi summary of Saudi telemedicine licensing; MOH telehealth regulations PDF (valid till March 2022, check for successor). | F152: Al Tamimi KSA telemedicine; Saudi MOH regulations | G152: law | H152: https://www.tamimi.com/law-update-articles/the-regulation-and-licensing-of-telemedicine-in-saudi-arabia
A153: Q2 | B153: Regulatory items to settle with counsel | C153: UAE: the patient's location sets the regulator; Abu Dhabi allows telecounselling from outside the UAE but telediagnosis only between licensed facilities; DHA Telehealth Standard requires electronic consent before each consultation, Arabic and English interfaces, UAE-based servers, no remote controlled-substance prescribing. | D153: Scope, consent per session, architecture | E153: Kayrouz & Associates; Al Tamimi UAE; Neelim 2026. | F153: Kayrouz, UAE telehealth licensing and data | G153: law | H153: https://www.kayrouzandassociates.com/insights/licensing-and-data-rules-for-telehealth-providers-in-the-uae
A154: Q3 | B154: Regulatory items to settle with counsel | C154: UAE health data may not be stored, processed or transferred outside the UAE without health-authority approval (Federal Law 2 of 2019, Art. 13; fines AED 500k to 700k; 25-year retention). Plan data residency or an approval route before UAE launch. | D154: Architecture, privacy, records upload | E154: Al Tamimi; Clifford Chance 2025. | F154: Al Tamimi, UAE ICT Health Law | G154: law | H154: https://tamimi.com/law-update-articles/the-federal-law-regulating-the-use-of-information-and-communication-technology-in-the-uae-healthcare-sector
A155: Q4 | B155: Regulatory items to settle with counsel | C155: Saudi PDPL cross-border transfer needs adequacy, standard clauses or a derogation; confirm the health-data position with counsel. | D155: Architecture, privacy | E155: Clifford Chance 2025 (does not address health data specifically). | F155: Clifford Chance, Data transfers UAE and KSA | G155: law | H155: https://www.cliffordchance.com/insights/resources/blogs/talking-tech/en/articles/2025/03/doing-business-in-the-middle-east--data-transfers-in-the-uae-and-ksa.html
A156: Q5 | B156: Regulatory items to settle with counsel | C156: Kuwait, Qatar, Oman, Bahrain: no cross-border telemedicine rules found in this research (regulators: Kuwait MOH, QCHP, Oman MOH, NHRA). Treat as a gap for counsel. | D156: Scope | E156: Neelim 2026 covers only UAE and KSA. | F156: Neelim, GCC telemedicine licensing 2026 | G156: practitioner | H156: https://neelim.com/blog/telemedicine-licensing-gcc-2026
A157: Q6 | B157: Regulatory items to settle with counsel | C157: California AB 3030 (from 1 Jan 2025): AI-generated patient communications about clinical information must disclose AI generation and how to reach a human, unless a licensed provider reviewed them. Apply to the summary and the intake chat regardless of state. | D157: Summary viewer, intake chat | E157: Duane Morris alert. | F157: Duane Morris on AB 3030 | G157: law | H157: https://www.duanemorris.com/alerts/california_passes_novel_law_governing_generative_ai_healthcare_1224.html
